test-case1.py
Traceback (most recent call last):
  File "C:\Users\Test3\AppData\Roaming\Python\Python310\site-packages\urllib3\connection.py", line 198, in _new_conn
    sock = connection.create_connection(
  File "C:\Users\Test3\AppData\Roaming\Python\Python310\site-packages\urllib3\util\connection.py", line 85, in create_connection
    raise err
  File "C:\Users\Test3\AppData\Roaming\Python\Python310\site-packages\urllib3\util\connection.py", line 73, in create_connection
    sock.connect(sa)
ConnectionRefusedError: [WinError 10061] No connection could be made because the target machine actively refused it

The above exception was the direct cause of the following exception:

Traceback (most recent call last):
  File "C:\Users\Test3\AppData\Roaming\Python\Python310\site-packages\urllib3\connectionpool.py", line 787, in urlopen
    response = self._make_request(
  File "C:\Users\Test3\AppData\Roaming\Python\Python310\site-packages\urllib3\connectionpool.py", line 493, in _make_request
    conn.request(
  File "C:\Users\Test3\AppData\Roaming\Python\Python310\site-packages\urllib3\connection.py", line 445, in request
    self.endheaders()
  File "C:\Program Files\Python310\lib\http\client.py", line 1271, in endheaders
    self._send_output(message_body, encode_chunked=encode_chunked)
  File "C:\Program Files\Python310\lib\http\client.py", line 1031, in _send_output
    self.send(msg)
  File "C:\Program Files\Python310\lib\http\client.py", line 969, in send
    self.connect()
  File "C:\Users\Test3\AppData\Roaming\Python\Python310\site-packages\urllib3\connection.py", line 276, in connect
    self.sock = self._new_conn()
  File "C:\Users\Test3\AppData\Roaming\Python\Python310\site-packages\urllib3\connection.py", line 213, in _new_conn
    raise NewConnectionError(
urllib3.exceptions.NewConnectionError: <urllib3.connection.HTTPConnection object at 0x000001A1ACA24B50>: Failed to establish a new connection: [WinError 10061] No connection could be made because the target machine actively refused it

The above exception was the direct cause of the following exception:

Traceback (most recent call last):
  File "C:\Users\Test3\Desktop\automation\rms\test-case1.py", line 14, in <module>
    driver = webdriver.Remote(
  File "C:\Users\Test3\AppData\Roaming\Python\Python310\site-packages\appium\webdriver\webdriver.py", line 238, in __init__
    super().__init__(
  File "C:\Users\Test3\AppData\Roaming\Python\Python310\site-packages\selenium\webdriver\remote\webdriver.py", line 250, in __init__
    self.start_session(capabilities)
  File "C:\Users\Test3\AppData\Roaming\Python\Python310\site-packages\appium\webdriver\webdriver.py", line 329, in start_session
    response = self.execute(RemoteCommand.NEW_SESSION, w3c_caps)
  File "C:\Users\Test3\AppData\Roaming\Python\Python310\site-packages\selenium\webdriver\remote\webdriver.py", line 427, in execute
    response = self.command_executor.execute(driver_command, params)
  File "C:\Users\Test3\AppData\Roaming\Python\Python310\site-packages\selenium\webdriver\remote\remote_connection.py", line 404, in execute
    return self._request(command_info[0], url, body=data)
  File "C:\Users\Test3\AppData\Roaming\Python\Python310\site-packages\selenium\webdriver\remote\remote_connection.py", line 428, in _request
    response = self._conn.request(method, url, body=body, headers=headers, timeout=self._client_config.timeout)
  File "C:\Users\Test3\AppData\Roaming\Python\Python310\site-packages\urllib3\_request_methods.py", line 143, in request
    return self.request_encode_body(
  File "C:\Users\Test3\AppData\Roaming\Python\Python310\site-packages\urllib3\_request_methods.py", line 278, in request_encode_body
    return self.urlopen(method, url, **extra_kw)
  File "C:\Users\Test3\AppData\Roaming\Python\Python310\site-packages\urllib3\poolmanager.py", line 443, in urlopen
    response = conn.urlopen(method, u.request_uri, **kw)
  File "C:\Users\Test3\AppData\Roaming\Python\Python310\site-packages\urllib3\connectionpool.py", line 871, in urlopen
    return self.urlopen(
  File "C:\Users\Test3\AppData\Roaming\Python\Python310\site-packages\urllib3\connectionpool.py", line 871, in urlopen
    return self.urlopen(
  File "C:\Users\Test3\AppData\Roaming\Python\Python310\site-packages\urllib3\connectionpool.py", line 871, in urlopen
    return self.urlopen(
  File "C:\Users\Test3\AppData\Roaming\Python\Python310\site-packages\urllib3\connectionpool.py", line 841, in urlopen
    retries = retries.increment(
  File "C:\Users\Test3\AppData\Roaming\Python\Python310\site-packages\urllib3\util\retry.py", line 519, in increment
    raise MaxRetryError(_pool, url, reason) from reason  # type: ignore[arg-type]
urllib3.exceptions.MaxRetryError: HTTPConnectionPool(host='127.0.0.1', port=4723): Max retries exceeded with url: /session (Caused by NewConnectionError('<urllib3.connection.HTTPConnection object at 0x000001A1ACA24B50>: Failed to establish a new connection: [WinError 10061] No connection could be made because the target machine actively refused it'))
